{
 "cells": [
  {
   "cell_type": "code",
   "execution_count": 4,
   "metadata": {},
   "outputs": [],
   "source": [
    "import cv2\n",
    "from keras.models import load_model\n",
    "from keras_preprocessing.image import img_to_array\n",
    "from keras.preprocessing import image\n",
    "from PIL import ImageFont, ImageDraw, Image \n",
    "import numpy as np"
   ]
  },
  {
   "cell_type": "code",
   "execution_count": 5,
   "metadata": {},
   "outputs": [],
   "source": [
    "model_path = 'D:/DHBK/KI8/DATN/AI/src/emotion_detection.h5'"
   ]
  },
  {
   "cell_type": "code",
   "execution_count": 6,
   "metadata": {},
   "outputs": [
    {
     "name": "stdout",
     "output_type": "stream",
     "text": [
      "Error loading the model: Error when deserializing class 'Conv2D' using config={'name': 'conv2d', 'trainable': True, 'dtype': 'float32', 'filters': 32, 'kernel_size': [3, 3], 'strides': [2, 2], 'padding': 'same', 'data_format': 'channels_last', 'dilation_rate': [1, 1], 'activation': 'linear', 'use_bias': True, 'kernel_initializer': {'class_name': 'VarianceScaling', 'config': {'scale': 1.0, 'mode': 'fan_avg', 'distribution': 'uniform', 'seed': None, 'dtype': 'float32'}}, 'bias_initializer': {'class_name': 'Zeros', 'config': {'dtype': 'float32'}}, 'kernel_regularizer': None, 'bias_regularizer': None, 'activity_regularizer': None, 'kernel_constraint': None, 'bias_constraint': None}.\n",
      "\n",
      "Exception encountered: <class 'keras.src.initializers.random_initializers.VarianceScaling'> could not be deserialized properly. Please ensure that components that are Python object instances (layers, models, etc.) returned by `get_config()` are explicitly deserialized in the model's `from_config()` method.\n",
      "\n",
      "config={'module': 'keras.initializers', 'class_name': 'VarianceScaling', 'config': {'scale': 1.0, 'mode': 'fan_avg', 'distribution': 'uniform', 'seed': None, 'dtype': 'float32'}, 'registered_name': None}.\n",
      "\n",
      "Exception encountered: VarianceScaling.__init__() got an unexpected keyword argument 'dtype'\n"
     ]
    }
   ],
   "source": [
    "try:\n",
    "    classifier = load_model(model_path)\n",
    "    print(\"Model loaded successfully!\")\n",
    "except Exception as e:\n",
    "    print(\"Error loading the model:\", e)"
   ]
  }
 ],
 "metadata": {
  "kernelspec": {
   "display_name": "Python 3",
   "language": "python",
   "name": "python3"
  },
  "language_info": {
   "codemirror_mode": {
    "name": "ipython",
    "version": 3
   },
   "file_extension": ".py",
   "mimetype": "text/x-python",
   "name": "python",
   "nbconvert_exporter": "python",
   "pygments_lexer": "ipython3",
   "version": "3.12.2"
  }
 },
 "nbformat": 4,
 "nbformat_minor": 2
}
